Workbook

Sheet Resumo
A1: RESUMO EXECUTIVO — VIABILIDADE
A2: Last Mile Elétrico | Belo Horizonte | Frota inicial 4 furgões
A4: Investimento inicial (CAPEX) | C4: =CAPEX!$D$11 -> 1130000
A5: OPEX anual (frota cheia) | C5: =OPEX!$C$14 -> 421429.2
A7: Indicador | B7: Conservador | C7: Realista | D7: Premium
A8: VPL (R$) | B8: ='Projeção & Viabilidade'!C21 -> -1531254.2 | C8: ='Projeção & Viabilidade'!C42 -> -814721.25 | D8: ='Projeção & Viabilidade'!C63 -> 188424.91
A9: TIR (a.a.) | B9: ='Projeção & Viabilidade'!C22 -> -1 | C9: ='Projeção & Viabilidade'!C43 -> -0.08794825 | D9: ='Projeção & Viabilidade'!C64 -> 0.2333873
A10: Payback descontado (anos) | B10: ='Projeção & Viabilidade'!C23 -> 6 | C10: ='Projeção & Viabilidade'!C44 -> 6 | D10: ='Projeção & Viabilidade'!C65 -> 5
A11: Margem EBITDA (Ano 3) | B11: ='Projeção & Viabilidade'!F14 -> -0.29325192 | C11: ='Projeção & Viabilidade'!F35 -> 0.20368077 | D11: ='Projeção & Viabilidade'!F56 -> 0.43558269
A12: Receita Ano 3 (R$) | B12: ='Projeção & Viabilidade'!F9 -> 385482.24 | C12: ='Projeção & Viabilidade'!F30 -> 706717.44 | D12: ='Projeção & Viabilidade'!F51 -> 1156446.7
A14: Veredito (VPL vs. 0 e TIR vs. TMA 18%): | B14: =IF('Projeção & Viabilidade'!C21>0,"VIÁVEL","INVIÁVEL") -> INVIÁVEL | C14: =IF('Projeção & Viabilidade'!C42>0,"VIÁVEL","INVIÁVEL") -> INVIÁVEL | D14: =IF('Projeção & Viabilidade'!C63>0,"VIÁVEL","INVIÁVEL") -> VIÁVEL
A16: LEITURA RÁPIDA
A17: • A viabilidade NÃO depende do furgão — depende do PREÇO/posicionamento. Com a mesma frota, o negócio
A18: perde dinheiro como agregado puro (commodity) e só remunera o capital no nicho expresso/B2B.
A19: • O capex de frota elétrica nova é o que afunda o cenário realista. Alavancas: frota seminova/combustão,
A20: começar com 2 furgões, ou ancorar 1-2 contratos âncora antes de comprar veículos.
A21: • Edite as células AZUIS na aba Premissas para testar suas próprias hipóteses.

Sheet Premissas
A1: IMOBAI Logística — Last Mile Elétrico BH | PREMISSAS
A2: Células azuis = inputs editáveis. Altere para rodar seus próprios cenários.
A4: OPERACIONAIS
A5: Nº de furgões (frota inicial) | B5: 3
A6: Entregas por furgão / dia (produtivas) | B6: 75 | C6: dropoffs/dia em rota densa
A7: Dias úteis / mês | B7: 22
A8: Entregas / ano (100% capacidade) | B8: =B5*B6*B7*12 -> 59400
A10: CURVA DE MATURAÇÃO (ocupação da frota)
A11: Ano 1 | B11: 0.65
A12: Ano 2 | B12: 0.85
A13: Ano 3 | B13: 1
A14: Ano 4 | B14: 1.05 | C14: leve expansão de demanda
A15: Ano 5 | B15: 1.1
A17: PREÇO MÉDIO POR ENTREGA (R$) — driver de cenário
A18: Cenário Conservador (commodity ML/Amazon) | B18: 6 | C18: preço de agregado puro
A19: Cenário Realista (mix commodity + alguns expressos) | B19: 11
A20: Cenário Premium (nicho expresso/B2B/alto valor) | B20: 18
A21: Reajuste de preço a.a. | B21: 0.04
A23: CUSTO DE PESSOAL
A24: Nº motoristas | B24: =B5 -> 3
A25: Salário motorista / mês | B25: 3000
A26: Encargos sobre salário | B26: 0.7 | C26: CLT: ~70% (INSS, FGTS, férias, 13º, etc.)
A27: Salário coordenador de operação / mês | B27: 0
A29: ENERGIA (recarga elétrica)
A30: km por furgão / dia | B30: 150 | C30: real urbano BH; eT3 autonomia ~170km
A31: Consumo (kWh / km) | B31: 0.22
A32: Tarifa de energia (R$ / kWh) | B32: 0.95 | C32: comercial CEMIG aprox.
A34: OUTROS CUSTOS MENSAIS
A35: Aluguel base / cross-dock | B35: 5000 | C35: galpão ~250m² região metro BH
A36: Seguro por furgão / mês | B36: 900 | C36: EV de alto valor encarece
A37: Manutenção por furgão / mês | B37: 450 | C37: EV: baixa, sem câmbio/injeção
A38: Software / TMS / roteirização / mês | B38: 2200
A39: Telecom / dispositivos / mês | B39: 1500
A40: Admin / contábil / jurídico / mês | B40: 3500
A41: Marketing / vendas / mês | B41: 1500
A43: TRIBUTOS E FINANCEIRO
A44: Impostos sobre receita (efetivo) | B44: 0.2 | C44: Simples/Presumido transporte — VALIDAR c/ contador
A45: TMA / taxa de desconto (a.a.) | B45: 0.18 | C45: Selic alta + prêmio de risco
A46: Reinvestimento (capex manut.) / ano | B46: 20000
A47: Valor residual da frota (% do capex veículos, ano 5) | B47: 0.35
...

Sheet CAPEX
A1: INVESTIMENTO INICIAL (CAPEX)
A3: Item | B3: Qtd | C3: Valor unitário (R$) | D3: Total (R$)
A4: Furgão elétrico BYD eT3 (novo) | B4: =Premissas!B5 -> 3 | C4: 260000 | D4: =B4*C4 -> 780000
A5: Infraestrutura de recarga (wallboxes + entrada de energia) | B5: 1 | C5: 40000 | D5: =B5*C5 -> 40000
A6: Setup base/cross-dock (prateleiras, segurança, TI) | B6: 1 | C6: 70000 | D6: =B6*C6 -> 70000
A7: Implantação de software / TMS | B7: 1 | C7: 40000 | D7: =B7*C7 -> 40000
A8: Scanners / dispositivos / coletores | B8: 1 | C8: 15000 | D8: =B8*C8 -> 15000
A9: Licenciamento e abertura (RNTRC, ANTT, contábil, jurídico) | B9: 1 | C9: 35000 | D9: =B9*C9 -> 35000
A10: Capital de giro inicial (colchão 2-3 meses) | B10: 1 | C10: 150000 | D10: =B10*C10 -> 150000
A11: TOTAL CAPEX | D11: =SUM(D4:D10) -> 1130000
A13: Nota: frota elétrica nova ~ dobra o capex de veículos vs. combustão seminova (Fiorino/Kangoo ~R$110-170k).

Sheet OPEX
A1: CUSTO OPERACIONAL (OPEX)
A3: Item | B3: Mensal (R$) | C3: Anual (R$)
A4: Motoristas (frota) | B4: =Premissas!B24*Premissas!B25*(1+Premissas!B26) -> 15300 | C4: =B4*12 -> 183600
A5: Coordenador de operação | B5: =Premissas!B27*(1+Premissas!B26) -> 0 | C5: =B5*12 -> 0
A6: Energia / recarga | B6: =Premissas!B5*Premissas!B30*Premissas!B7*Premissas!B31*Premissas!B32 -> 2069.1 | C6: =B6*12 -> 24829.2
A7: Aluguel base / cross-dock | B7: =Premissas!B35 -> 5000 | C7: =B7*12 -> 60000
A8: Seguro da frota | B8: =Premissas!B5*Premissas!B36 -> 2700 | C8: =B8*12 -> 32400
A9: Manutenção da frota | B9: =Premissas!B5*Premissas!B37 -> 1350 | C9: =B9*12 -> 16200
A10: Software / TMS | B10: =Premissas!B38 -> 2200 | C10: =B10*12 -> 26400
A11: Telecom / dispositivos | B11: =Premissas!B39 -> 1500 | C11: =B11*12 -> 18000
A12: Admin / contábil / jurídico | B12: =Premissas!B40 -> 3500 | C12: =B12*12 -> 42000
A13: Marketing / vendas | B13: =Premissas!B41 -> 1500 | C13: =B13*12 -> 18000
A14: TOTAL OPEX | B14: =SUM(B4:B13) -> 35119.1 | C14: =SUM(C4:C13) -> 421429.2

Sheet Projeção & Viabilidade
A1: PROJEÇÃO 5 ANOS, FLUXO DE CAIXA E VIABILIDADE
C3: Ano 0 | D3: Ano 1 | E3: Ano 2 | F3: Ano 3 | G3: Ano 4 | H3: Ano 5
A5: CENÁRIO CONSERVADOR (commodity)
A6: Ocupação da frota (%) | D6: =Premissas!$B$11 -> 0.65 | E6: =Premissas!$B$12 -> 0.85 | F6: =Premissas!$B$13 -> 1 | G6: =Premissas!$B$14 -> 1.05 | H6: =Premissas!$B$15 -> 1.1
A7: Volume (entregas/ano) | D7: =Premissas!$B$8*D6 -> 38610 | E7: =Premissas!$B$8*E6 -> 50490 | F7: =Premissas!$B$8*F6 -> 59400 | G7: =Premissas!$B$8*G6 -> 62370 | H7: =Premissas!$B$8*H6 -> 65340
A8: Preço médio (R$/entrega) | D8: =Premissas!$B$18*(1+Premissas!$B$21)^0 -> 6 | E8: =Premissas!$B$18*(1+Premissas!$B$21)^1 -> 6.24 | F8: =Premissas!$B$18*(1+Premissas!$B$21)^2 -> 6.4896 | G8: =Premissas!$B$18*(1+Premissas!$B$21)^3 -> 6.749184 | H8: =Premissas!$B$18*(1+Premissas!$B$21)^4 -> 7.0191514
A9: Receita Bruta | D9: =D7*D8 -> 231660 | E9: =E7*E8 -> 315057.6 | F9: =F7*F8 -> 385482.24 | G9: =G7*G8 -> 420946.61 | H9: =H7*H8 -> 458631.35
A10: (-) Impostos sobre receita | D10: =-D9*Premissas!$B$44 -> -46332 | E10: =-E9*Premissas!$B$44 -> -63011.52 | F10: =-F9*Premissas!$B$44 -> -77096.448 | G10: =-G9*Premissas!$B$44 -> -84189.321 | H10: =-H9*Premissas!$B$44 -> -91726.27
A11: Receita Líquida | D11: =D9+D10 -> 185328 | E11: =E9+E10 -> 252046.08 | F11: =F9+F10 -> 308385.79 | G11: =G9+G10 -> 336757.28 | H11: =H9+H10 -> 366905.08
A12: (-) OPEX (custos operacionais) | D12: =-OPEX!$C$14 -> -421429.2 | E12: =-OPEX!$C$14 -> -421429.2 | F12: =-OPEX!$C$14 -> -421429.2 | G12: =-OPEX!$C$14 -> -421429.2 | H12: =-OPEX!$C$14 -> -421429.2
A13: EBITDA | D13: =D11+D12 -> -236101.2 | E13: =E11+E12 -> -169383.12 | F13: =F11+F12 -> -113043.41 | G13: =G11+G12 -> -84671.915 | H13: =H11+H12 -> -54524.12
A14: Margem EBITDA (%) | D14: =IF(D9=0,0,D13/D9) -> -1.0191712 | E14: =IF(E9=0,0,E13/E9) -> -0.53762588 | F14: =IF(F9=0,0,F13/F9) -> -0.29325192 | G14: =IF(G9=0,0,G13/G9) -> -0.20114645 | H14: =IF(H9=0,0,H13/H9) -> -0.11888442
A15: (-) Depreciação | D15: =-((CAPEX!$D$11-CAPEX!$D$10)/Premissas!$B$48) -> -196000 | E15: =-((CAPEX!$D$11-CAPEX!$D$10)/Premissas!$B$48) -> -196000 | F15: =-((CAPEX!$D$11-CAPEX!$D$10)/Premissas!$B$48) -> -196000 | G15: =-((CAPEX!$D$11-CAPEX!$D$10)/Premissas!$B$48) -> -196000 | H15: =-((CAPEX!$D$11-CAPEX!$D$10)/Premissas!$B$48) -> -196000
A16: EBIT | D16: =D13+D15 -> -432101.2 | E16: =E13+E15 -> -365383.12 | F16: =F13+F15 -> -309043.41 | G16: =G13+G15 -> -280671.92 | H16: =H13+H15 -> -250524.12
A17: Fluxo de Caixa Livre | C17: =-CAPEX!$D$11 -> -1130000 | D17: =D13-Premissas!$B$46 -> -256101.2 | E17: =E13-Premissas!$B$46 -> -189383.12 | F17: =F13-Premissas!$B$46 -> -133043.41 | G17: =G13-Premissas!$B$46 -> -104671.92 | H17: =H13-Premissas!$B$46+Premissas!$B$47*CAPEX!$D$4 -> 198475.88
A18: FCL descontado | C18: =C17 -> -1130000 | D18: =D17/(1+Premissas!$B$45)^1 -> -217034.92 | E18: =E17/(1+Premissas!$B$45)^2 -> -136012.01 | F18: =F17/(1+Premissas!$B$45)^3 -> -80974.326 | G18: =G17/(1+Premissas!$B$45)^4 -> -53988.609 | H18: =H17/(1+Premissas!$B$45)^5 -> 86755.636
A19: FCL descontado acumulado | C19: =C18 -> -1130000 | D19: =C19+D18 -> -1347034.9 | E19: =D19+E18 -> -1483046.9 | F19: =E19+F18 -> -1564021.2 | G19: =F19+G18 -> -1618009.9 | H19: =G19+H18 -> -1531254.2
A21: VPL (Valor Presente Líquido) | C21: =C17+NPV(Premissas!$B$45,D17:H17) -> -1531254.2
A22: TIR (Taxa Interna de Retorno) | C22: =IFERROR(IRR(C17:H17),-1) -> -1
A23: Payback descontado (anos, aprox.) | C23: =COUNTIF(C19:H19,"<0") -> 6
A26: CENÁRIO REALISTA (mix)
A27: Ocupação da frota (%) | D27: =Premissas!$B$11 -> 0.65 | E27: =Premissas!$B$12 -> 0.85 | F27: =Premissas!$B$13 -> 1 | G27: =Premissas!$B$14 -> 1.05 | H27: =Premissas!$B$15 -> 1.1
A28: Volume (entregas/ano) | D28: =Premissas!$B$8*D27 -> 38610 | E28: =Premissas!$B$8*E27 -> 50490 | F28: =Premissas!$B$8*F27 -> 59400 | G28: =Premissas!$B$8*G27 -> 62370 | H28: =Premissas!$B$8*H27 -> 65340
A29: Preço médio (R$/entrega) | D29: =Premissas!$B$19*(1+Premissas!$B$21)^0 -> 11 | E29: =Premissas!$B$19*(1+Premissas!$B$21)^1 -> 11.44 | F29: =Premissas!$B$19*(1+Premissas!$B$21)^2 -> 11.8976 | G29: =Premissas!$B$19*(1+Premissas!$B$21)^3 -> 12.373504 | H29: =Premissas!$B$19*(1+Premissas!$B$21)^4 -> 12.868444
A30: Receita Bruta | D30: =D28*D29 -> 424710 | E30: =E28*E29 -> 577605.6 | F30: =F28*F29 -> 706717.44 | G30: =G28*G29 -> 771735.44 | H30: =H28*H29 -> 840824.14
A31: (-) Impostos sobre receita | D31: =-D30*Premissas!$B$44 -> -84942 | E31: =-E30*Premissas!$B$44 -> -115521.12 | F31: =-F30*Premissas!$B$44 -> -141343.49 | G31: =-G30*Premissas!$B$44 -> -154347.09 | H31: =-H30*Premissas!$B$44 -> -168164.83
A32: Receita Líquida | D32: =D30+D31 -> 339768 | E32: =E30+E31 -> 462084.48 | F32: =F30+F31 -> 565373.95 | G32: =G30+G31 -> 617388.36 | H32: =H30+H31 -> 672659.31
A33: (-) OPEX (custos operacionais) | D33: =-OPEX!$C$14 -> -421429.2 | E33: =-OPEX!$C$14 -> -421429.2 | F33: =-OPEX!$C$14 -> -421429.2 | G33: =-OPEX!$C$14 -> -421429.2 | H33: =-OPEX!$C$14 -> -421429.2
A34: EBITDA | D34: =D32+D33 -> -81661.2 | E34: =E32+E33 -> 40655.28 | F34: =F32+F33 -> 143944.75 | G34: =G32+G33 -> 195959.16 | H34: =H32+H33 -> 251230.11
A35: Margem EBITDA (%) | D35: =IF(D30=0,0,D34/D30) -> -0.1922752 | E35: =IF(E30=0,0,E34/E30) -> 0.070385883 | F35: =IF(F30=0,0,F34/F30) -> 0.20368077 | G35: =IF(G30=0,0,G34/G30) -> 0.25392012 | H35: =IF(H30=0,0,H34/H30) -> 0.29879032
A36: (-) Depreciação | D36: =-((CAPEX!$D$11-CAPEX!$D$10)/Premissas!$B$48) -> -196000 | E36: =-((CAPEX!$D$11-CAPEX!$D$10)/Premissas!$B$48) -> -196000 | F36: =-((CAPEX!$D$11-CAPEX!$D$10)/Premissas!$B$48) -> -196000 | G36: =-((CAPEX!$D$11-CAPEX!$D$10)/Premissas!$B$48) -> -196000 | H36: =-((CAPEX!$D$11-CAPEX!$D$10)/Premissas!$B$48) -> -196000
A37: EBIT | D37: =D34+D36 -> -277661.2 | E37: =E34+E36 -> -155344.72 | F37: =F34+F36 -> -52055.248 | G37: =G34+G36 -> -40.844416 | H37: =H34+H36 -> 55230.113
A38: Fluxo de Caixa Livre | C38: =-CAPEX!$D$11 -> -1130000 | D38: =D34-Premissas!$B$46 -> -101661.2 | E38: =E34-Premissas!$B$46 -> 20655.28 | F38: =F34-Premissas!$B$46 -> 123944.75 | G38: =G34-Premissas!$B$46 -> 175959.16 | H38: =H34-Premissas!$B$46+Premissas!$B$47*CAPEX!$D$4 -> 504230.11
A39: FCL descontado | C39: =C38 -> -1130000 | D39: =D38/(1+Premissas!$B$45)^1 -> -86153.559 | E39: =E38/(1+Premissas!$B$45)^2 -> 14834.3 | F39: =F38/(1+Premissas!$B$45)^3 -> 75436.603 | G39: =G38/(1+Premissas!$B$45)^4 -> 90757.775 | H39: =H38/(1+Premissas!$B$45)^5 -> 220403.63
A40: FCL descontado acumulado | C40: =C39 -> -1130000 | D40: =C40+D39 -> -1216153.6 | E40: =D40+E39 -> -1201319.3 | F40: =E40+F39 -> -1125882.7 | G40: =F40+G39 -> -1035124.9 | H40: =G40+H39 -> -814721.25
A42: VPL (Valor Presente Líquido) | C42: =C38+NPV(Premissas!$B$45,D38:H38) -> -814721.25
A43: TIR (Taxa Interna de Retorno) | C43: =IFERROR(IRR(C38:H38),-1) -> -0.08794825
A44: Payback descontado (anos, aprox.) | C44: =COUNTIF(C40:H40,"<0") -> 6
A47: CENÁRIO PREMIUM (nicho expresso)
A48: Ocupação da frota (%) | D48: =Premissas!$B$11 -> 0.65 | E48: =Premissas!$B$12 -> 0.85 | F48: =Premissas!$B$13 -> 1 | G48: =Premissas!$B$14 -> 1.05 | H48: =Premissas!$B$15 -> 1.1
...
